Traceback (most recent call last):
  File "/srv/conda/envs/notebook/lib/python3.10/site-packages/jupyter_cache/executors/utils.py", line 58, in single_nb_execution
    executenb(
  File "/srv/conda/envs/notebook/lib/python3.10/site-packages/nbclient/client.py", line 1093, in execute
    return NotebookClient(nb=nb, resources=resources, km=km, **kwargs).execute()
  File "/srv/conda/envs/notebook/lib/python3.10/site-packages/nbclient/util.py", line 84, in wrapped
    return just_run(coro(*args, **kwargs))
  File "/srv/conda/envs/notebook/lib/python3.10/site-packages/nbclient/util.py", line 62, in just_run
    return loop.run_until_complete(coro)
  File "/srv/conda/envs/notebook/lib/python3.10/asyncio/base_events.py", line 649, in run_until_complete
    return future.result()
  File "/srv/conda/envs/notebook/lib/python3.10/site-packages/nbclient/client.py", line 559, in async_execute
    await self.async_execute_cell(
  File "/srv/conda/envs/notebook/lib/python3.10/site-packages/nbclient/client.py", line 854, in async_execute_cell
    self._check_raise_for_error(cell, exec_reply)
  File "/srv/conda/envs/notebook/lib/python3.10/site-packages/nbclient/client.py", line 756, in _check_raise_for_error
    raise CellExecutionError.from_cell_and_msg(cell, exec_reply_content)
nbclient.exceptions.CellExecutionError: An error occurred while executing the following cell:
------------------
ul.create_map(counts_df_clean, zips = 'Zip', feature = 'counts')
------------------

[0;31m---------------------------------------------------------------------------[0m
[0;31mAttributeError[0m                            Traceback (most recent call last)
Cell [0;32mIn[8], line 1[0m
[0;32m----> 1[0m [43mul[49m[38;5;241;43m.[39;49m[43mcreate_map[49m(counts_df_clean, zips [38;5;241m=[39m [38;5;124m'[39m[38;5;124mZip[39m[38;5;124m'[39m, feature [38;5;241m=[39m [38;5;124m'[39m[38;5;124mcounts[39m[38;5;124m'[39m)

[0;31mAttributeError[0m: module 'tools.utils' has no attribute 'create_map'
AttributeError: module 'tools.utils' has no attribute 'create_map'

